<?xml version="1.0" ?>
<!-- =================================================================================== -->
<!-- |    This document was autogenerated by xacro from excelsus.xacro                 | -->
<!-- |    EDITING THIS FILE BY HAND IS NOT RECOMMENDED                                 | -->
<!-- =================================================================================== -->
<robot name="excelsus">
  <material name="silver_default">
    <color rgba="0.700 0.700 0.700 1.000"/>
  </material>
  <material name="opaque246246243">
    <color rgba="0.9647058823529412 0.9647058823529412 0.9529411764705882 1.0"/>
  </material>
  <material name="epx_150_air_baked_with_carbon_m2_m3_l1_3d_printers">
    <color rgba="0.24705882352941178 0.24705882352941178 0.24705882352941178 1.0"/>
  </material>
  <transmission name="RearLeftJoint2_tran">
    <type>transmission_interface/SimpleTransmission</type>
    <joint name="RearLeftJoint2">
      <hardwareInterface>hardware_interface/EffortJointInterface</hardwareInterface>
    </joint>
    <actuator name="RearLeftJoint2_actr">
      <hardwareInterface>hardware_interface/EffortJointInterface</hardwareInterface>
      <mechanicalReduction>1</mechanicalReduction>
    </actuator>
  </transmission>
  <transmission name="RearLeftJoint1_tran">
    <type>transmission_interface/SimpleTransmission</type>
    <joint name="RearLeftJoint1">
      <hardwareInterface>hardware_interface/EffortJointInterface</hardwareInterface>
    </joint>
    <actuator name="RearLeftJoint1_actr">
      <hardwareInterface>hardware_interface/EffortJointInterface</hardwareInterface>
      <mechanicalReduction>1</mechanicalReduction>
    </actuator>
  </transmission>
  <transmission name="RearLeftJoint0_tran">
    <type>transmission_interface/SimpleTransmission</type>
    <joint name="RearLeftJoint0">
      <hardwareInterface>hardware_interface/EffortJointInterface</hardwareInterface>
    </joint>
    <actuator name="RearLeftJoint0_actr">
      <hardwareInterface>hardware_interface/EffortJointInterface</hardwareInterface>
      <mechanicalReduction>1</mechanicalReduction>
    </actuator>
  </transmission>
  <transmission name="FrontLeftJoint2_tran">
    <type>transmission_interface/SimpleTransmission</type>
    <joint name="FrontLeftJoint2">
      <hardwareInterface>hardware_interface/EffortJointInterface</hardwareInterface>
    </joint>
    <actuator name="FrontLeftJoint2_actr">
      <hardwareInterface>hardware_interface/EffortJointInterface</hardwareInterface>
      <mechanicalReduction>1</mechanicalReduction>
    </actuator>
  </transmission>
  <transmission name="FrontLeftJoint1_tran">
    <type>transmission_interface/SimpleTransmission</type>
    <joint name="FrontLeftJoint1">
      <hardwareInterface>hardware_interface/EffortJointInterface</hardwareInterface>
    </joint>
    <actuator name="FrontLeftJoint1_actr">
      <hardwareInterface>hardware_interface/EffortJointInterface</hardwareInterface>
      <mechanicalReduction>1</mechanicalReduction>
    </actuator>
  </transmission>
  <transmission name="FrontLeftJoint0_tran">
    <type>transmission_interface/SimpleTransmission</type>
    <joint name="FrontLeftJoint0">
      <hardwareInterface>hardware_interface/EffortJointInterface</hardwareInterface>
    </joint>
    <actuator name="FrontLeftJoint0_actr">
      <hardwareInterface>hardware_interface/EffortJointInterface</hardwareInterface>
      <mechanicalReduction>1</mechanicalReduction>
    </actuator>
  </transmission>
  <transmission name="FrontRightJoint2_tran">
    <type>transmission_interface/SimpleTransmission</type>
    <joint name="FrontRightJoint2">
      <hardwareInterface>hardware_interface/EffortJointInterface</hardwareInterface>
    </joint>
    <actuator name="FrontRightJoint2_actr">
      <hardwareInterface>hardware_interface/EffortJointInterface</hardwareInterface>
      <mechanicalReduction>1</mechanicalReduction>
    </actuator>
  </transmission>
  <transmission name="FrontRightJoint1_tran">
    <type>transmission_interface/SimpleTransmission</type>
    <joint name="FrontRightJoint1">
      <hardwareInterface>hardware_interface/EffortJointInterface</hardwareInterface>
    </joint>
    <actuator name="FrontRightJoint1_actr">
      <hardwareInterface>hardware_interface/EffortJointInterface</hardwareInterface>
      <mechanicalReduction>1</mechanicalReduction>
    </actuator>
  </transmission>
  <transmission name="FrontRightJoint0_tran">
    <type>transmission_interface/SimpleTransmission</type>
    <joint name="FrontRightJoint0">
      <hardwareInterface>hardware_interface/EffortJointInterface</hardwareInterface>
    </joint>
    <actuator name="FrontRightJoint0_actr">
      <hardwareInterface>hardware_interface/EffortJointInterface</hardwareInterface>
      <mechanicalReduction>1</mechanicalReduction>
    </actuator>
  </transmission>
  <transmission name="RearRightJoint2_tran">
    <type>transmission_interface/SimpleTransmission</type>
    <joint name="RearRightJoint2">
      <hardwareInterface>hardware_interface/EffortJointInterface</hardwareInterface>
    </joint>
    <actuator name="RearRightJoint2_actr">
      <hardwareInterface>hardware_interface/EffortJointInterface</hardwareInterface>
      <mechanicalReduction>1</mechanicalReduction>
    </actuator>
  </transmission>
  <transmission name="RearRightJoint1_tran">
    <type>transmission_interface/SimpleTransmission</type>
    <joint name="RearRightJoint1">
      <hardwareInterface>hardware_interface/EffortJointInterface</hardwareInterface>
    </joint>
    <actuator name="RearRightJoint1_actr">
      <hardwareInterface>hardware_interface/EffortJointInterface</hardwareInterface>
      <mechanicalReduction>1</mechanicalReduction>
    </actuator>
  </transmission>
  <transmission name="RearRightJoint0_tran">
    <type>transmission_interface/SimpleTransmission</type>
    <joint name="RearRightJoint0">
      <hardwareInterface>hardware_interface/EffortJointInterface</hardwareInterface>
    </joint>
    <actuator name="RearRightJoint0_actr">
      <hardwareInterface>hardware_interface/EffortJointInterface</hardwareInterface>
      <mechanicalReduction>1</mechanicalReduction>
    </actuator>
  </transmission>
  <transmission name="RearLeftJoint4_tran">
    <type>transmission_interface/SimpleTransmission</type>
    <joint name="RearLeftJoint4">
      <hardwareInterface>hardware_interface/EffortJointInterface</hardwareInterface>
    </joint>
    <actuator name="RearLeftJoint4_actr">
      <hardwareInterface>hardware_interface/EffortJointInterface</hardwareInterface>
      <mechanicalReduction>1</mechanicalReduction>
    </actuator>
  </transmission>
  <transmission name="RearLeftJoint3_tran">
    <type>transmission_interface/SimpleTransmission</type>
    <joint name="RearLeftJoint3">
      <hardwareInterface>hardware_interface/EffortJointInterface</hardwareInterface>
    </joint>
    <actuator name="RearLeftJoint3_actr">
      <hardwareInterface>hardware_interface/EffortJointInterface</hardwareInterface>
      <mechanicalReduction>1</mechanicalReduction>
    </actuator>
  </transmission>
  <transmission name="FrontLeftJoint4_tran">
    <type>transmission_interface/SimpleTransmission</type>
    <joint name="FrontLeftJoint4">
      <hardwareInterface>hardware_interface/EffortJointInterface</hardwareInterface>
    </joint>
    <actuator name="FrontLeftJoint4_actr">
      <hardwareInterface>hardware_interface/EffortJointInterface</hardwareInterface>
      <mechanicalReduction>1</mechanicalReduction>
    </actuator>
  </transmission>
  <transmission name="FrontLeftJoint3_tran">
    <type>transmission_interface/SimpleTransmission</type>
    <joint name="FrontLeftJoint3">
      <hardwareInterface>hardware_interface/EffortJointInterface</hardwareInterface>
    </joint>
    <actuator name="FrontLeftJoint3_actr">
      <hardwareInterface>hardware_interface/EffortJointInterface</hardwareInterface>
      <mechanicalReduction>1</mechanicalReduction>
    </actuator>
  </transmission>
  <transmission name="FrontRightJoint4_tran">
    <type>transmission_interface/SimpleTransmission</type>
    <joint name="FrontRightJoint4">
      <hardwareInterface>hardware_interface/EffortJointInterface</hardwareInterface>
    </joint>
    <actuator name="FrontRightJoint4_actr">
      <hardwareInterface>hardware_interface/EffortJointInterface</hardwareInterface>
      <mechanicalReduction>1</mechanicalReduction>
    </actuator>
  </transmission>
  <transmission name="FrontRightJoint3_tran">
    <type>transmission_interface/SimpleTransmission</type>
    <joint name="FrontRightJoint3">
      <hardwareInterface>hardware_interface/EffortJointInterface</hardwareInterface>
    </joint>
    <actuator name="FrontRightJoint3_actr">
      <hardwareInterface>hardware_interface/EffortJointInterface</hardwareInterface>
      <mechanicalReduction>1</mechanicalReduction>
    </actuator>
  </transmission>
  <transmission name="RearRightJoint4_tran">
    <type>transmission_interface/SimpleTransmission</type>
    <joint name="RearRightJoint4">
      <hardwareInterface>hardware_interface/EffortJointInterface</hardwareInterface>
    </joint>
    <actuator name="RearRightJoint4_actr">
      <hardwareInterface>hardware_interface/EffortJointInterface</hardwareInterface>
      <mechanicalReduction>1</mechanicalReduction>
    </actuator>
  </transmission>
  <transmission name="RearRightJoint3_tran">
    <type>transmission_interface/SimpleTransmission</type>
    <joint name="RearRightJoint3">
      <hardwareInterface>hardware_interface/EffortJointInterface</hardwareInterface>
    </joint>
    <actuator name="RearRightJoint3_actr">
      <hardwareInterface>hardware_interface/EffortJointInterface</hardwareInterface>
      <mechanicalReduction>1</mechanicalReduction>
    </actuator>
  </transmission>
  <gazebo>
    <plugin filename="libgazebo_ros_control.so" name="control"/>
  </gazebo>
  <gazebo reference="base_link">
    <material>Gazebo/Silver</material>
    <mu1>0.2</mu1>
    <mu2>0.2</mu2>
    <selfCollide>true</selfCollide>
    <gravity>true</gravity>
  </gazebo>
  <gazebo reference="rear-left-middle-leg_1">
    <material>Gazebo/Silver</material>
    <mu1>0.2</mu1>
    <mu2>0.2</mu2>
    <selfCollide>true</selfCollide>
  </gazebo>
  <gazebo reference="rear-left-upper-leg_1">
    <material>Gazebo/Silver</material>
    <mu1>0.2</mu1>
    <mu2>0.2</mu2>
    <selfCollide>true</selfCollide>
  </gazebo>
  <gazebo reference="rear-left-base-leg_1">
    <material>Gazebo/Silver</material>
    <mu1>0.2</mu1>
    <mu2>0.2</mu2>
    <selfCollide>true</selfCollide>
  </gazebo>
  <gazebo reference="front-left-middle-leg_1">
    <material>Gazebo/Silver</material>
    <mu1>0.2</mu1>
    <mu2>0.2</mu2>
    <selfCollide>true</selfCollide>
  </gazebo>
  <gazebo reference="front-left-upper-leg_1">
    <material>Gazebo/Silver</material>
    <mu1>0.2</mu1>
    <mu2>0.2</mu2>
    <selfCollide>true</selfCollide>
  </gazebo>
  <gazebo reference="front-left-base-leg_1">
    <material>Gazebo/Silver</material>
    <mu1>0.2</mu1>
    <mu2>0.2</mu2>
    <selfCollide>true</selfCollide>
  </gazebo>
  <gazebo reference="front-right-middle-leg_1">
    <material>Gazebo/Silver</material>
    <mu1>0.2</mu1>
    <mu2>0.2</mu2>
    <selfCollide>true</selfCollide>
  </gazebo>
  <gazebo reference="front-right-upper-leg_1">
    <material>Gazebo/Silver</material>
    <mu1>0.2</mu1>
    <mu2>0.2</mu2>
    <selfCollide>true</selfCollide>
  </gazebo>
  <gazebo reference="front-right-base-leg_1">
    <material>Gazebo/Silver</material>
    <mu1>0.2</mu1>
    <mu2>0.2</mu2>
    <selfCollide>true</selfCollide>
  </gazebo>
  <gazebo reference="rear-right-middle-leg_1">
    <material>Gazebo/Silver</material>
    <mu1>0.2</mu1>
    <mu2>0.2</mu2>
    <selfCollide>true</selfCollide>
  </gazebo>
  <gazebo reference="rear-right-upper-leg_1">
    <material>Gazebo/Silver</material>
    <mu1>0.2</mu1>
    <mu2>0.2</mu2>
    <selfCollide>true</selfCollide>
  </gazebo>
  <gazebo reference="rear-right-base-leg_1">
    <material>Gazebo/Silver</material>
    <mu1>0.2</mu1>
    <mu2>0.2</mu2>
    <selfCollide>true</selfCollide>
  </gazebo>
  <gazebo reference="rear-left-craw_1">
    <material>Gazebo/Silver</material>
    <mu1>0.2</mu1>
    <mu2>0.2</mu2>
    <selfCollide>true</selfCollide>
  </gazebo>
  <gazebo reference="rear-left-lower-leg_1">
    <material>Gazebo/Silver</material>
    <mu1>0.2</mu1>
    <mu2>0.2</mu2>
    <selfCollide>true</selfCollide>
  </gazebo>
  <gazebo reference="front-left-craw_1">
    <material>Gazebo/Silver</material>
    <mu1>0.2</mu1>
    <mu2>0.2</mu2>
    <selfCollide>true</selfCollide>
  </gazebo>
  <gazebo reference="front-left-lower-leg_1">
    <material>Gazebo/Silver</material>
    <mu1>0.2</mu1>
    <mu2>0.2</mu2>
    <selfCollide>true</selfCollide>
  </gazebo>
  <gazebo reference="front-right-craw_1">
    <material>Gazebo/Silver</material>
    <mu1>0.2</mu1>
    <mu2>0.2</mu2>
    <selfCollide>true</selfCollide>
  </gazebo>
  <gazebo reference="front-right-lower-leg_1">
    <material>Gazebo/Silver</material>
    <mu1>0.2</mu1>
    <mu2>0.2</mu2>
    <selfCollide>true</selfCollide>
  </gazebo>
  <gazebo reference="rear-right-craw_1">
    <material>Gazebo/Silver</material>
    <mu1>0.2</mu1>
    <mu2>0.2</mu2>
    <selfCollide>true</selfCollide>
  </gazebo>
  <gazebo reference="rear-right-lower-leg_1">
    <material>Gazebo/Silver</material>
    <mu1>0.2</mu1>
    <mu2>0.2</mu2>
    <selfCollide>true</selfCollide>
  </gazebo>
  <link name="base_link">
    <inertial>
      <origin rpy="0 0 0" xyz="-5.030033392761689e-17 -0.00029569010956729944 -0.0007681503352656508"/>
      <mass value="1.125665971469736"/>
      <inertia ixx="0.001968" ixy="-3e-06" ixz="-0.0" iyy="0.002703" iyz="0.0" izz="0.004398"/>
    </inertial>
    <visual>
      <origin rpy="0 0 0" xyz="0 0 0"/>
      <geometry>
        <mesh filename="package://excelsus_description/meshes/base_link.stl" scale="0.001 0.001 0.001"/>
      </geometry>
      <material name="opaque246246243"/>
    </visual>
    <collision>
      <origin rpy="0 0 0" xyz="0 0 0"/>
      <geometry>
        <mesh filename="package://excelsus_description/meshes/base_link.stl" scale="0.001 0.001 0.001"/>
      </geometry>
    </collision>
  </link>
  <link name="rear-left-middle-leg_1">
    <inertial>
      <origin rpy="0 0 0" xyz="0.03662487154399953 -0.014211363327568671 -0.0346386088514269"/>
      <mass value="0.4219440312643297"/>
      <inertia ixx="0.000366" ixy="1e-06" ixz="8.3e-05" iyy="0.000391" iyz="-0.0" izz="9.8e-05"/>
    </inertial>
    <visual>
      <origin rpy="0 0 0" xyz="-0.1115 -0.056904 -0.051877"/>
      <geometry>
        <mesh filename="package://excelsus_description/meshes/rear-left-middle-leg_1.stl" scale="0.001 0.001 0.001"/>
      </geometry>
      <material name="opaque246246243"/>
    </visual>
    <collision>
      <origin rpy="0 0 0" xyz="-0.1115 -0.056904 -0.051877"/>
      <geometry>
        <mesh filename="package://excelsus_description/meshes/rear-left-middle-leg_1.stl" scale="0.001 0.001 0.001"/>
      </geometry>
    </collision>
  </link>
  <link name="rear-left-upper-leg_1">
    <inertial>
      <origin rpy="0 0 0" xyz="6.523326043211819e-05 -0.014144819518955569 0.03686031239871101"/>
      <mass value="0.24064580815886535"/>
      <inertia ixx="8.2e-05" ixy="0.0" ixz="-0.0" iyy="7.3e-05" iyz="1e-06" izz="3.4e-05"/>
    </inertial>
    <visual>
      <origin rpy="0 0 0" xyz="-0.1115 -0.057204 0.001123"/>
      <geometry>
        <mesh filename="package://excelsus_description/meshes/rear-left-upper-leg_1.stl" scale="0.001 0.001 0.001"/>
      </geometry>
      <material name="epx_150_air_baked_with_carbon_m2_m3_l1_3d_printers"/>
    </visual>
    <collision>
      <origin rpy="0 0 0" xyz="-0.1115 -0.057204 0.001123"/>
      <geometry>
        <mesh filename="package://excelsus_description/meshes/rear-left-upper-leg_1.stl" scale="0.001 0.001 0.001"/>
      </geometry>
    </collision>
  </link>
  <link name="rear-left-base-leg_1">
    <inertial>
      <origin rpy="0 0 0" xyz="0.03316988831276137 7.009790016201944e-05 -0.014273316157971089"/>
      <mass value="0.22271760560239287"/>
      <inertia ixx="3.1e-05" ixy="0.0" ixz="1e-06" iyy="6.2e-05" iyz="-0.0" izz="5.9e-05"/>
    </inertial>
    <visual>
      <origin rpy="0 0 0" xyz="-0.0645 -0.043204 -0.013177"/>
      <geometry>
        <mesh filename="package://excelsus_description/meshes/rear-left-base-leg_1.stl" scale="0.001 0.001 0.001"/>
      </geometry>
      <material name="epx_150_air_baked_with_carbon_m2_m3_l1_3d_printers"/>
    </visual>
    <collision>
      <origin rpy="0 0 0" xyz="-0.0645 -0.043204 -0.013177"/>
      <geometry>
        <mesh filename="package://excelsus_description/meshes/rear-left-base-leg_1.stl" scale="0.001 0.001 0.001"/>
      </geometry>
    </collision>
  </link>
  <link name="front-left-middle-leg_1">
    <inertial>
      <origin rpy="0 0 0" xyz="0.03662487154399953 0.014088636672431903 -0.03463860885142715"/>
      <mass value="0.4219440312643297"/>
      <inertia ixx="0.000366" ixy="1e-06" ixz="8.3e-05" iyy="0.000391" iyz="-0.0" izz="9.8e-05"/>
    </inertial>
    <visual>
      <origin rpy="0 0 0" xyz="-0.1115 0.057796 -0.051877"/>
      <geometry>
        <mesh filename="package://excelsus_description/meshes/front-left-middle-leg_1.stl" scale="0.001 0.001 0.001"/>
      </geometry>
      <material name="opaque246246243"/>
    </visual>
    <collision>
      <origin rpy="0 0 0" xyz="-0.1115 0.057796 -0.051877"/>
      <geometry>
        <mesh filename="package://excelsus_description/meshes/front-left-middle-leg_1.stl" scale="0.001 0.001 0.001"/>
      </geometry>
    </collision>
  </link>
  <link name="front-left-upper-leg_1">
    <inertial>
      <origin rpy="0 0 0" xyz="6.523326045146383e-05 0.014155180480418326 0.036860312398532415"/>
      <mass value="0.2406458081588655"/>
      <inertia ixx="8.2e-05" ixy="0.0" ixz="-0.0" iyy="7.3e-05" iyz="1e-06" izz="3.4e-05"/>
    </inertial>
    <visual>
      <origin rpy="0 0 0" xyz="-0.1115 0.057796 0.001123"/>
      <geometry>
        <mesh filename="package://excelsus_description/meshes/front-left-upper-leg_1.stl" scale="0.001 0.001 0.001"/>
      </geometry>
      <material name="epx_150_air_baked_with_carbon_m2_m3_l1_3d_printers"/>
    </visual>
    <collision>
      <origin rpy="0 0 0" xyz="-0.1115 0.057796 0.001123"/>
      <geometry>
        <mesh filename="package://excelsus_description/meshes/front-left-upper-leg_1.stl" scale="0.001 0.001 0.001"/>
      </geometry>
    </collision>
  </link>
  <link name="front-left-base-leg_1">
    <inertial>
      <origin rpy="0 0 0" xyz="0.03316988831276123 7.009790016202638e-05 -0.014273316157970225"/>
      <mass value="0.2227176056023929"/>
      <inertia ixx="3.1e-05" ixy="0.0" ixz="1e-06" iyy="6.2e-05" iyz="-0.0" izz="5.9e-05"/>
    </inertial>
    <visual>
      <origin rpy="0 0 0" xyz="-0.0645 0.043796 -0.013177"/>
      <geometry>
        <mesh filename="package://excelsus_description/meshes/front-left-base-leg_1.stl" scale="0.001 0.001 0.001"/>
      </geometry>
      <material name="epx_150_air_baked_with_carbon_m2_m3_l1_3d_printers"/>
    </visual>
    <collision>
      <origin rpy="0 0 0" xyz="-0.0645 0.043796 -0.013177"/>
      <geometry>
        <mesh filename="package://excelsus_description/meshes/front-left-base-leg_1.stl" scale="0.001 0.001 0.001"/>
      </geometry>
    </collision>
  </link>
  <link name="front-right-middle-leg_1">
    <inertial>
      <origin rpy="0 0 0" xyz="-0.036624871543999224 0.014211983108469377 -0.03463860885142524"/>
      <mass value="0.4219440312643297"/>
      <inertia ixx="0.000366" ixy="1e-06" ixz="-8.3e-05" iyy="0.000391" iyz="0.0" izz="9.8e-05"/>
    </inertial>
    <visual>
      <origin rpy="0 0 0" xyz="0.1115 0.057496 -0.051877"/>
      <geometry>
        <mesh filename="package://excelsus_description/meshes/front-right-middle-leg_1.stl" scale="0.001 0.001 0.001"/>
      </geometry>
      <material name="opaque246246243"/>
    </visual>
    <collision>
      <origin rpy="0 0 0" xyz="0.1115 0.057496 -0.051877"/>
      <geometry>
        <mesh filename="package://excelsus_description/meshes/front-right-middle-leg_1.stl" scale="0.001 0.001 0.001"/>
      </geometry>
    </collision>
  </link>
  <link name="front-right-upper-leg_1">
    <inertial>
      <origin rpy="0 0 0" xyz="-6.523326043220146e-05 0.014145439299855359 0.03686031239871269"/>
      <mass value="0.24064580815886535"/>
      <inertia ixx="8.2e-05" ixy="0.0" ixz="0.0" iyy="7.3e-05" iyz="-1e-06" izz="3.4e-05"/>
    </inertial>
    <visual>
      <origin rpy="0 0 0" xyz="0.1115 0.057796 0.001123"/>
      <geometry>
        <mesh filename="package://excelsus_description/meshes/front-right-upper-leg_1.stl" scale="0.001 0.001 0.001"/>
      </geometry>
      <material name="epx_150_air_baked_with_carbon_m2_m3_l1_3d_printers"/>
    </visual>
    <collision>
      <origin rpy="0 0 0" xyz="0.1115 0.057796 0.001123"/>
      <geometry>
        <mesh filename="package://excelsus_description/meshes/front-right-upper-leg_1.stl" scale="0.001 0.001 0.001"/>
      </geometry>
    </collision>
  </link>
  <link name="front-right-base-leg_1">
    <inertial>
      <origin rpy="0 0 0" xyz="-0.033169888312761464 -6.947811926222985e-05 -0.014273316157969668"/>
      <mass value="0.22271760560239287"/>
      <inertia ixx="3.1e-05" ixy="0.0" ixz="-1e-06" iyy="6.2e-05" iyz="0.0" izz="5.9e-05"/>
    </inertial>
    <visual>
      <origin rpy="0 0 0" xyz="0.0645 0.043796 -0.013177"/>
      <geometry>
        <mesh filename="package://excelsus_description/meshes/front-right-base-leg_1.stl" scale="0.001 0.001 0.001"/>
      </geometry>
      <material name="epx_150_air_baked_with_carbon_m2_m3_l1_3d_printers"/>
    </visual>
    <collision>
      <origin rpy="0 0 0" xyz="0.0645 0.043796 -0.013177"/>
      <geometry>
        <mesh filename="package://excelsus_description/meshes/front-right-base-leg_1.stl" scale="0.001 0.001 0.001"/>
      </geometry>
    </collision>
  </link>
  <link name="rear-right-middle-leg_1">
    <inertial>
      <origin rpy="0 0 0" xyz="-0.03662487154399986 -0.014088016891530546 -0.034638608851427076"/>
      <mass value="0.4219440312643297"/>
      <inertia ixx="0.000366" ixy="1e-06" ixz="-8.3e-05" iyy="0.000391" iyz="0.0" izz="9.8e-05"/>
    </inertial>
    <visual>
      <origin rpy="0 0 0" xyz="0.1115 -0.057204 -0.051877"/>
      <geometry>
        <mesh filename="package://excelsus_description/meshes/rear-right-middle-leg_1.stl" scale="0.001 0.001 0.001"/>
      </geometry>
      <material name="opaque246246243"/>
    </visual>
    <collision>
      <origin rpy="0 0 0" xyz="0.1115 -0.057204 -0.051877"/>
      <geometry>
        <mesh filename="package://excelsus_description/meshes/rear-right-middle-leg_1.stl" scale="0.001 0.001 0.001"/>
      </geometry>
    </collision>
  </link>
  <link name="rear-right-upper-leg_1">
    <inertial>
      <origin rpy="0 0 0" xyz="-6.523326043235411e-05 -0.014154560700144606 0.03686031239871122"/>
      <mass value="0.24064580815886538"/>
      <inertia ixx="8.2e-05" ixy="0.0" ixz="0.0" iyy="7.3e-05" iyz="-1e-06" izz="3.4e-05"/>
    </inertial>
    <visual>
      <origin rpy="0 0 0" xyz="0.1115 -0.057204 0.001123"/>
      <geometry>
        <mesh filename="package://excelsus_description/meshes/rear-right-upper-leg_1.stl" scale="0.001 0.001 0.001"/>
      </geometry>
      <material name="epx_150_air_baked_with_carbon_m2_m3_l1_3d_printers"/>
    </visual>
    <collision>
      <origin rpy="0 0 0" xyz="0.1115 -0.057204 0.001123"/>
      <geometry>
        <mesh filename="package://excelsus_description/meshes/rear-right-upper-leg_1.stl" scale="0.001 0.001 0.001"/>
      </geometry>
    </collision>
  </link>
  <link name="rear-right-base-leg_1">
    <inertial>
      <origin rpy="0 0 0" xyz="-0.033169888312761284 -6.947811926216046e-05 -0.014273316157970999"/>
      <mass value="0.2227176056023929"/>
      <inertia ixx="3.1e-05" ixy="0.0" ixz="-1e-06" iyy="6.2e-05" iyz="0.0" izz="5.9e-05"/>
    </inertial>
    <visual>
      <origin rpy="0 0 0" xyz="0.0645 -0.043204 -0.013177"/>
      <geometry>
        <mesh filename="package://excelsus_description/meshes/rear-right-base-leg_1.stl" scale="0.001 0.001 0.001"/>
      </geometry>
      <material name="epx_150_air_baked_with_carbon_m2_m3_l1_3d_printers"/>
    </visual>
    <collision>
      <origin rpy="0 0 0" xyz="0.0645 -0.043204 -0.013177"/>
      <geometry>
        <mesh filename="package://excelsus_description/meshes/rear-right-base-leg_1.stl" scale="0.001 0.001 0.001"/>
      </geometry>
    </collision>
  </link>
  <link name="rear-left-craw_1">
    <inertial>
      <origin rpy="0 0 0" xyz="-2.3946243918326893e-06 3.0989044990520354e-07 -0.0021710475035774945"/>
      <mass value="0.0032125334253544006"/>
      <inertia ixx="0.0" ixy="0.0" ixz="-0.0" iyy="0.0" iyz="0.0" izz="0.0"/>
    </inertial>
    <visual>
      <origin rpy="0 0 0" xyz="-0.153864 -0.052804 0.071568"/>
      <geometry>
        <mesh filename="package://excelsus_description/meshes/rear-left-craw_1.stl" scale="0.001 0.001 0.001"/>
      </geometry>
      <material name="epx_150_air_baked_with_carbon_m2_m3_l1_3d_printers"/>
    </visual>
    <collision>
      <origin rpy="0 0 0" xyz="-0.153864 -0.052804 0.071568"/>
      <geometry>
        <mesh filename="package://excelsus_description/meshes/rear-left-craw_1.stl" scale="0.001 0.001 0.001"/>
      </geometry>
    </collision>
  </link>
  <link name="rear-left-lower-leg_1">
    <inertial>
      <origin rpy="0 0 0" xyz="-5.1416892328209896e-05 -0.011888882526507272 -0.032619644830111594"/>
      <mass value="0.2261109161031503"/>
      <inertia ixx="6.2e-05" ixy="0.0" ixz="-0.0" iyy="5e-05" iyz="3e-06" izz="3.5e-05"/>
    </inertial>
    <visual>
      <origin rpy="0 0 0" xyz="-0.154 -0.056604 0.018623"/>
      <geometry>
        <mesh filename="package://excelsus_description/meshes/rear-left-lower-leg_1.stl" scale="0.001 0.001 0.001"/>
      </geometry>
      <material name="epx_150_air_baked_with_carbon_m2_m3_l1_3d_printers"/>
    </visual>
    <collision>
      <origin rpy="0 0 0" xyz="-0.154 -0.056604 0.018623"/>
      <geometry>
        <mesh filename="package://excelsus_description/meshes/rear-left-lower-leg_1.stl" scale="0.001 0.001 0.001"/>
      </geometry>
    </collision>
  </link>
  <link name="front-left-craw_1">
    <inertial>
      <origin rpy="0 0 0" xyz="2.1245051555485173e-06 3.098904506060318e-07 -0.0021710027440375868"/>
      <mass value="0.0032125334253544006"/>
      <inertia ixx="0.0" ixy="-0.0" ixz="0.0" iyy="0.0" iyz="0.0" izz="0.0"/>
    </inertial>
    <visual>
      <origin rpy="0 0 0" xyz="-0.153864 0.054596 0.071678"/>
      <geometry>
        <mesh filename="package://excelsus_description/meshes/front-left-craw_1.stl" scale="0.001 0.001 0.001"/>
      </geometry>
      <material name="epx_150_air_baked_with_carbon_m2_m3_l1_3d_printers"/>
    </visual>
    <collision>
      <origin rpy="0 0 0" xyz="-0.153864 0.054596 0.071678"/>
      <geometry>
        <mesh filename="package://excelsus_description/meshes/front-left-craw_1.stl" scale="0.001 0.001 0.001"/>
      </geometry>
    </collision>
  </link>
  <link name="front-left-lower-leg_1">
    <inertial>
      <origin rpy="0 0 0" xyz="-0.00019048025029058668 -0.01651832705013496 -0.032699923981751075"/>
      <mass value="0.22611091610315037"/>
      <inertia ixx="6.3e-05" ixy="-0.0" ixz="-0.0" iyy="5e-05" iyz="-4e-06" izz="3.5e-05"/>
    </inertial>
    <visual>
      <origin rpy="0 0 0" xyz="-0.154 0.029796 0.018623"/>
      <geometry>
        <mesh filename="package://excelsus_description/meshes/front-left-lower-leg_1.stl" scale="0.001 0.001 0.001"/>
      </geometry>
      <material name="epx_150_air_baked_with_carbon_m2_m3_l1_3d_printers"/>
    </visual>
    <collision>
      <origin rpy="0 0 0" xyz="-0.154 0.029796 0.018623"/>
      <geometry>
        <mesh filename="package://excelsus_description/meshes/front-left-lower-leg_1.stl" scale="0.001 0.001 0.001"/>
      </geometry>
    </collision>
  </link>
  <link name="front-right-craw_1">
    <inertial>
      <origin rpy="0 0 0" xyz="-2.412367960169526e-06 3.098904509946099e-07 -0.002171047503575649"/>
      <mass value="0.0032125334253544006"/>
      <inertia ixx="0.0" ixy="0.0" ixz="-0.0" iyy="0.0" iyz="-0.0" izz="0.0"/>
    </inertial>
    <visual>
      <origin rpy="0 0 0" xyz="0.153864 0.053396 0.071568"/>
      <geometry>
        <mesh filename="package://excelsus_description/meshes/front-right-craw_1.stl" scale="0.001 0.001 0.001"/>
      </geometry>
      <material name="epx_150_air_baked_with_carbon_m2_m3_l1_3d_printers"/>
    </visual>
    <collision>
      <origin rpy="0 0 0" xyz="0.153864 0.053396 0.071568"/>
      <geometry>
        <mesh filename="package://excelsus_description/meshes/front-right-craw_1.stl" scale="0.001 0.001 0.001"/>
      </geometry>
    </collision>
  </link>
  <link name="front-right-lower-leg_1">
    <inertial>
      <origin rpy="0 0 0" xyz="5.1416892328154384e-05 0.011889502307408178 -0.03261964483010979"/>
      <mass value="0.22611091610315034"/>
      <inertia ixx="6.2e-05" ixy="0.0" ixz="0.0" iyy="5e-05" iyz="-3e-06" izz="3.5e-05"/>
    </inertial>
    <visual>
      <origin rpy="0 0 0" xyz="0.154 0.057196 0.018623"/>
      <geometry>
        <mesh filename="package://excelsus_description/meshes/front-right-lower-leg_1.stl" scale="0.001 0.001 0.001"/>
      </geometry>
      <material name="epx_150_air_baked_with_carbon_m2_m3_l1_3d_printers"/>
    </visual>
    <collision>
      <origin rpy="0 0 0" xyz="0.154 0.057196 0.018623"/>
      <geometry>
        <mesh filename="package://excelsus_description/meshes/front-right-lower-leg_1.stl" scale="0.001 0.001 0.001"/>
      </geometry>
    </collision>
  </link>
  <link name="rear-right-craw_1">
    <inertial>
      <origin rpy="0 0 0" xyz="-2.1245051574914076e-06 3.0989045091134315e-07 -0.002171002744037351"/>
      <mass value="0.0032125334253544006"/>
      <inertia ixx="0.0" ixy="-0.0" ixz="-0.0" iyy="0.0" iyz="-0.0" izz="0.0"/>
    </inertial>
    <visual>
      <origin rpy="0 0 0" xyz="0.153864 -0.054004 0.071678"/>
      <geometry>
        <mesh filename="package://excelsus_description/meshes/rear-right-craw_1.stl" scale="0.001 0.001 0.001"/>
      </geometry>
      <material name="epx_150_air_baked_with_carbon_m2_m3_l1_3d_printers"/>
    </visual>
    <collision>
      <origin rpy="0 0 0" xyz="0.153864 -0.054004 0.071678"/>
      <geometry>
        <mesh filename="package://excelsus_description/meshes/rear-right-craw_1.stl" scale="0.001 0.001 0.001"/>
      </geometry>
    </collision>
  </link>
  <link name="rear-right-lower-leg_1">
    <inertial>
      <origin rpy="0 0 0" xyz="0.0001904802502888936 0.016518946831036524 -0.032699923981750895"/>
      <mass value="0.22611091610315037"/>
      <inertia ixx="6.3e-05" ixy="-0.0" ixz="0.0" iyy="5e-05" iyz="4e-06" izz="3.5e-05"/>
    </inertial>
    <visual>
      <origin rpy="0 0 0" xyz="0.154 -0.029204 0.018623"/>
      <geometry>
        <mesh filename="package://excelsus_description/meshes/rear-right-lower-leg_1.stl" scale="0.001 0.001 0.001"/>
      </geometry>
      <material name="epx_150_air_baked_with_carbon_m2_m3_l1_3d_printers"/>
    </visual>
    <collision>
      <origin rpy="0 0 0" xyz="0.154 -0.029204 0.018623"/>
      <geometry>
        <mesh filename="package://excelsus_description/meshes/rear-right-lower-leg_1.stl" scale="0.001 0.001 0.001"/>
      </geometry>
    </collision>
  </link>
  <joint name="RearLeftJoint2" type="continuous">
    <origin rpy="0 0 0" xyz="0.0 -0.0003 0.053"/>
    <parent link="rear-left-upper-leg_1"/>
    <child link="rear-left-middle-leg_1"/>
    <axis xyz="0.0 -1.0 0.0"/>
    <limit effort="0.48" velocity="6.55" lower="0.0" upper="3.14"/>
  </joint>
  <joint name="RearLeftJoint1" type="continuous">
    <origin rpy="0 0 0" xyz="0.047 0.014 -0.0143"/>
    <parent link="rear-left-base-leg_1"/>
    <child link="rear-left-upper-leg_1"/>
    <axis xyz="0.0 1.0 -0.0"/>
    <limit effort="0.48" velocity="6.55" lower="-1.57" upper="1.57"/>
  </joint>
  <joint name="RearLeftJoint0" type="continuous">
    <origin rpy="0 0 0" xyz="0.0645 0.043204 0.013177"/>
    <parent link="base_link"/>
    <child link="rear-left-base-leg_1"/>
    <axis xyz="-0.0 -0.0 1.0"/>
    <limit effort="0.48" velocity="6.55" lower="-1.04" upper="1.57"/>
  </joint>
  <joint name="FrontLeftJoint2" type="continuous">
    <origin rpy="0 0 0" xyz="0.0 0.0 0.053"/>
    <parent link="front-left-upper-leg_1"/>
    <child link="front-left-middle-leg_1"/>
    <axis xyz="0.0 -1.0 -0.0"/>
    <limit effort="0.48" velocity="6.55" lower="0.0" upper="3.14"/>
  </joint>
  <joint name="FrontLeftJoint1" type="continuous">
    <origin rpy="0 0 0" xyz="0.047 -0.014 -0.0143"/>
    <parent link="front-left-base-leg_1"/>
    <child link="front-left-upper-leg_1"/>
    <axis xyz="-0.0 1.0 -0.0"/>
    <limit effort="0.48" velocity="6.55" lower="-1.57" upper="1.57"/>
  </joint>
  <joint name="FrontLeftJoint0" type="continuous">
    <origin rpy="0 0 0" xyz="0.0645 -0.043796 0.013177"/>
    <parent link="base_link"/>
    <child link="front-left-base-leg_1"/>
    <axis xyz="-0.0 -0.0 -1.0"/>
    <limit effort="0.48" velocity="6.55" lower="-1.04" upper="1.57"/>
  </joint>
  <joint name="FrontRightJoint2" type="continuous">
    <origin rpy="0 0 0" xyz="0.0 0.0003 0.053"/>
    <parent link="front-right-upper-leg_1"/>
    <child link="front-right-middle-leg_1"/>
    <axis xyz="-0.0 1.0 -0.0"/>
    <limit effort="0.48" velocity="6.55" lower="0.0" upper="3.14"/>
  </joint>
  <joint name="FrontRightJoint1" type="continuous">
    <origin rpy="0 0 0" xyz="-0.047 -0.014 -0.0143"/>
    <parent link="front-right-base-leg_1"/>
    <child link="front-right-upper-leg_1"/>
    <axis xyz="-0.0 -1.0 -0.0"/>
    <limit effort="0.48" velocity="6.55" lower="-1.57" upper="1.57"/>
  </joint>
  <joint name="FrontRightJoint0" type="continuous">
    <origin rpy="0 0 0" xyz="-0.0645 -0.043796 0.013177"/>
    <parent link="base_link"/>
    <child link="front-right-base-leg_1"/>
    <axis xyz="0.0 0.0 1.0"/>
    <limit effort="0.48" velocity="6.55" lower="-1.04" upper="1.57"/>
  </joint>
  <joint name="RearRightJoint2" type="continuous">
    <origin rpy="0 0 0" xyz="0.0 0.0 0.053"/>
    <parent link="rear-right-upper-leg_1"/>
    <child link="rear-right-middle-leg_1"/>
    <axis xyz="-0.0 1.0 -0.0"/>
    <limit effort="0.48" velocity="6.55" lower="0.0" upper="3.14"/>
  </joint>
  <joint name="RearRightJoint1" type="continuous">
    <origin rpy="0 0 0" xyz="-0.047 0.014 -0.0143"/>
    <parent link="rear-right-base-leg_1"/>
    <child link="rear-right-upper-leg_1"/>
    <axis xyz="0.0 -1.0 -0.0"/>
    <limit effort="0.48" velocity="6.55" lower="-1.57" upper="1.57"/>
  </joint>
  <joint name="RearRightJoint0" type="continuous">
    <origin rpy="0 0 0" xyz="-0.0645 0.043204 0.013177"/>
    <parent link="base_link"/>
    <child link="rear-right-base-leg_1"/>
    <axis xyz="0.0 0.0 -1.0"/>
    <limit effort="0.48" velocity="6.55" lower="-1.04" upper="1.57"/>
  </joint>
  <joint name="RearLeftJoint4" type="continuous">
    <origin rpy="0 0 0" xyz="-0.000136 -0.0038 -0.052945"/>
    <parent link="rear-left-lower-leg_1"/>
    <child link="rear-left-craw_1"/>
    <axis xyz="0.0 -0.0 -1.0"/>
    <limit effort="0.48" velocity="6.55" lower="-3.14" upper="3.14"/>
  </joint>
  <joint name="RearLeftJoint3" type="continuous">
    <origin rpy="0 0 0" xyz="0.0425 -0.0003 -0.0705"/>
    <parent link="rear-left-middle-leg_1"/>
    <child link="rear-left-lower-leg_1"/>
    <axis xyz="0.0 -1.0 0.0"/>
    <limit effort="0.48" velocity="6.55" lower="-1.57" upper="1.57"/>
  </joint>
  <joint name="FrontLeftJoint4" type="continuous">
    <origin rpy="0 0 0" xyz="-0.000136 -0.0248 -0.053055"/>
    <parent link="front-left-lower-leg_1"/>
    <child link="front-left-craw_1"/>
    <axis xyz="0.0 0.0 1.0"/>
    <limit effort="0.48" velocity="6.55" lower="-3.14" upper="3.14"/>
  </joint>
  <joint name="FrontLeftJoint3" type="continuous">
    <origin rpy="0 0 0" xyz="0.0425 0.028 -0.0705"/>
    <parent link="front-left-middle-leg_1"/>
    <child link="front-left-lower-leg_1"/>
    <axis xyz="0.0 -1.0 -0.0"/>
    <limit effort="0.48" velocity="6.55" lower="-1.57" upper="1.57"/>
  </joint>
  <joint name="FrontRightJoint4" type="continuous">
    <origin rpy="0 0 0" xyz="0.000136 0.0038 -0.052945"/>
    <parent link="front-right-lower-leg_1"/>
    <child link="front-right-craw_1"/>
    <axis xyz="-0.0 -0.0 -1.0"/>
    <limit effort="0.48" velocity="6.55" lower="-3.14" upper="3.14"/>
  </joint>
  <joint name="FrontRightJoint3" type="continuous">
    <origin rpy="0 0 0" xyz="-0.0425 0.0003 -0.0705"/>
    <parent link="front-right-middle-leg_1"/>
    <child link="front-right-lower-leg_1"/>
    <axis xyz="0.0 1.0 0.0"/>
    <limit effort="0.48" velocity="6.55" lower="-1.57" upper="1.57"/>
  </joint>
  <joint name="RearRightJoint4" type="continuous">
    <origin rpy="0 0 0" xyz="0.000136 0.0248 -0.053055"/>
    <parent link="rear-right-lower-leg_1"/>
    <child link="rear-right-craw_1"/>
    <axis xyz="0.0 0.0 -1.0"/>
    <limit effort="0.48" velocity="6.55" lower="-3.14" upper="3.14"/>
  </joint>
  <joint name="RearRightJoint3" type="continuous">
    <origin rpy="0 0 0" xyz="-0.0425 -0.028 -0.0705"/>
    <parent link="rear-right-middle-leg_1"/>
    <child link="rear-right-lower-leg_1"/>
    <axis xyz="0.0 1.0 -0.0"/>
    <limit effort="0.48" velocity="6.55" lower="-1.57" upper="1.57"/>
  </joint>
</robot>

